Workbook

Sheet Index Match
A1: Order ID | B1: Customer ID | C1: City | D1: State | E1: Sales Channel | F1: Payment Method | G1: Product Category | H1: Brand | I1: Units Sold | J1: Unit Price | K1: Discount % | L1: Net Sales
A2: 10001 | B2: 1102 | C2: Chennai | D2: Delhi | E2: Mobile App | F2: Credit Card | G2: Home & Kitchen | H2: BrandA | I2: 7 | J2: 2843.87 | K2: 0 | L2: 19907.09 | N2: Serial No | O2: Value
A3: 10002 | B3: 1435 | C3: Pune | D3: Tamil Nadu | E3: Website | F3: Debit Card | G3: Sports | H3: BrandD | I3: 9 | J3: 2525.23 | K3: 5 | L3: 21590.72 | N3: 10 | O3: {=INDEX(A1:A501,N3)} -> 10009
A4: 10003 | B4: 1860 | C4: Chennai | D4: West Bengal | E4: Marketplace | F4: Debit Card | G4: Fashion | H4: BrandE | I4: 6 | J4: 3474.34 | K4: 15 | L4: 17719.13
A5: 10004 | B5: 1270 | C5: Bengaluru | D5: West Bengal | E5: Website | F5: Cash on Delivery | G5: Sports | H5: BrandA | I5: 1 | J5: 1008.79 | K5: 15 | L5: 857.47 | N5: Serial No | O5: Value
A6: 10005 | B6: 1106 | C6: Kolkata | D6: Karnataka | E6: Marketplace | F6: Credit Card | G6: Fashion | H6: BrandA | I6: 7 | J6: 3511.47 | K6: 20 | L6: 19664.23 | N6: 5 | O6: {=INDEX(A1:L1,,N6)} -> Sales Channel
A7: 10006 | B7: 1071 | C7: Hyderabad | D7: Telangana | E7: Website | F7: Net Banking | G7: Home & Kitchen | H7: BrandE | I7: 3 | J7: 3189.55 | K7: 10 | L7: 8611.78
A8: 10007 | B8: 1700 | C8: Bengaluru | D8: Telangana | E8: Mobile App | F8: UPI | G8: Fashion | H8: BrandC | I8: 5 | J8: 3030.42 | K8: 10 | L8: 13636.89 | N8: Row | O8: cloumn | P8: Value
A9: 10008 | B9: 1020 | C9: Mumbai | D9: Delhi | E9: Website | F9: Credit Card | G9: Fashion | H9: BrandB | I9: 4 | J9: 2310.83 | K9: 10 | L9: 8318.99 | N9: 3 | O9: 4 | P9: {=INDEX(A1:L501,N9,O9)} -> Tamil Nadu
A10: 10009 | B10: 1614 | C10: Chennai | D10: West Bengal | E10: Website | F10: Debit Card | G10: Fashion | H10: BrandD | I10: 5 | J10: 1098.04 | K10: 15 | L10: 4666.67
A11: 10010 | B11: 1121 | C11: Bengaluru | D11: Karnataka | E11: Website | F11: Cash on Delivery | G11: Electronics | H11: BrandB | I11: 5 | J11: 1780.66 | K11: 20 | L11: 7122.64 | N11: value | O11: position
A12: 10011 | B12: 1466 | C12: Bengaluru | D12: Karnataka | E12: Mobile App | F12: Cash on Delivery | G12: Electronics | H12: BrandE | I12: 6 | J12: 3205.25 | K12: 0 | L12: 19231.5 | N12: Unit Price | O12: =MATCH(N12,A1:L1,0) -> 10
A13: 10012 | B13: 1214 | C13: Mumbai | D13: Tamil Nadu | E13: Website | F13: UPI | G13: Electronics | H13: BrandA | I13: 6 | J13: 272.35 | K13: 5 | L13: 1552.39
A14: 10013 | B14: 1330 | C14: Delhi | D14: Tamil Nadu | E14: Mobile App | F14: Cash on Delivery | G14: Home & Kitchen | H14: BrandA | I14: 8 | J14: 3160.9 | K14: 0 | L14: 25287.2
A15: 10014 | B15: 1458 | C15: Kolkata | D15: Karnataka | E15: Marketplace | F15: Cash on Delivery | G15: Sports | H15: BrandD | I15: 8 | J15: 1074.27 | K15: 15 | L15: 7305.04 | N15: Customer ID | O15: Order ID | P15: Product Category
A16: 10015 | B16: 1087 | C16: Hyderabad | D16: Tamil Nadu | E16: Website | F16: Credit Card | G16: Beauty | H16: BrandA | I16: 9 | J16: 705.59 | K16: 10 | L16: 5715.28 | N16: 1270 | O16: =INDEX(A1:A501,MATCH(N16,B1:B501,0)) -> 10004 | P16: =INDEX(G1:G501,MATCH(N16,B1:B501,0)) -> Sports
A17: 10016 | B17: 1372 | C17: Pune | D17: West Bengal | E17: Mobile App | F17: Net Banking | G17: Fashion | H17: BrandA | I17: 8 | J17: 595.45 | K17: 5 | L17: 4525.42
A18: 10017 | B18: 1099 | C18: Delhi | D18: Maharashtra | E18: Mobile App | F18: UPI | G18: Fashion | H18: BrandD | I18: 2 | J18: 254.91 | K18: 15 | L18: 433.35 | N18: Order ID | O18: Payment Method
A19: 10018 | B19: 1871 | C19: Chennai | D19: West Bengal | E19: Website | F19: Credit Card | G19: Home & Kitchen | H19: BrandD | I19: 1 | J19: 2165.81 | K19: 15 | L19: 1840.94 | N19: 10002 | O19: =INDEX(A1:L501,MATCH(N19,A1:A501,0),MATCH(O18,A1:L1,0)) -> Debit Card
A20: 10019 | B20: 1663 | C20: Bengaluru | D20: Karnataka | E20: Marketplace | F20: Net Banking | G20: Fashion | H20: BrandE | I20: 2 | J20: 990.3 | K20: 15 | L20: 1683.51
A21: 10020 | B21: 1130 | C21: Mumbai | D21: Karnataka | E21: Mobile App | F21: Credit Card | G21: Electronics | H21: BrandA | I21: 2 | J21: 3959.31 | K21: 5 | L21: 7522.69
A22: 10021 | B22: 1661 | C22: Mumbai | D22: West Bengal | E22: Website | F22: Credit Card | G22: Beauty | H22: BrandA | I22: 3 | J22: 2361.58 | K22: 5 | L22: 6730.5
A23: 10022 | B23: 1308 | C23: Kolkata | D23: Tamil Nadu | E23: Marketplace | F23: Cash on Delivery | G23: Books | H23: BrandE | I23: 7 | J23: 680.86 | K23: 20 | L23: 3812.82
A24: 10023 | B24: 1769 | C24: Delhi | D24: Tamil Nadu | E24: Mobile App | F24: Net Banking | G24: Fashion | H24: BrandC | I24: 2 | J24: 2801.74 | K24: 20 | L24: 4482.78
A25: 10024 | B25: 1343 | C25: Pune | D25: Telangana | E25: Mobile App | F25: UPI | G25: Electronics | H25: BrandC | I25: 1 | J25: 3606.31 | K25: 0 | L25: 3606.31
A26: 10025 | B26: 1491 | C26: Kolkata | D26: Karnataka | E26: Marketplace | F26: UPI | G26: Books | H26: BrandC | I26: 6 | J26: 3018.94 | K26: 5 | L26: 17207.96
A27: 10026 | B27: 1413 | C27: Bengaluru | D27: Delhi | E27: Marketplace | F27: Net Banking | G27: Beauty | H27: BrandE | I27: 9 | J27: 444.29 | K27: 5 | L27: 3798.68
A28: 10027 | B28: 1805 | C28: Kolkata | D28: Telangana | E28: Website | F28: Cash on Delivery | G28: Books | H28: BrandA | I28: 3 | J28: 3599.15 | K28: 5 | L28: 10257.58
A29: 10028 | B29: 1385 | C29: Hyderabad | D29: Tamil Nadu | E29: Website | F29: Debit Card | G29: Electronics | H29: BrandE | I29: 6 | J29: 3206.63 | K29: 20 | L29: 15391.82
A30: 10029 | B30: 1191 | C30: Mumbai | D30: West Bengal | E30: Mobile App | F30: Credit Card | G30: Sports | H30: BrandE | I30: 3 | J30: 759.47 | K30: 15 | L30: 1936.65
A31: 10030 | B31: 1955 | C31: Mumbai | D31: Tamil Nadu | E31: Marketplace | F31: Cash on Delivery | G31: Sports | H31: BrandC | I31: 1 | J31: 349.38 | K31: 10 | L31: 314.44
... A501: 10500 | B501: 1569 | C501: Chennai | D501: Delhi | E501: Marketplace | F501: Net Banking | G501: Fashion | H501: BrandE | I501: 1 | J501: 2432.17 | K501: 20 | L501: 1945.74

Sheet Employees
A1: EmployeeID | B1: FirstName | C1: LastName | D1: Full Name | E1: Gender | F1: Age | G1: DepartmentID | H1: JobTitle | I1: HireDate | J1: Salary | K1: City | L1: Email | M1: Status | N1: Manager | O1: Maneger
A2: E0001 | B2: Amit | C2: Dutta | D2: =UPPER(_xlfn.CONCAT(B2," ",C2)) -> AMIT DUTTA | E2: Female | F2: 30 | G2: D01 | H2: Analyst | I2: 2019-02-21 | J2: 105257 | K2: Kolkata | L2: amit.dutta1@example.com | M2: Active | N2: =VLOOKUP(G2,Departments!A1:C6,3,0) -> Alice | O2: =INDEX(Departments!C1:C6,MATCH(Employees!G2,Departments!A1:A6,0)) -> Alice | Q2: Number of Female employee | T2: =COUNTIF(E2:E501,"Female") -> 249
A3: E0002 | B3: Amit | C3: Roy | D3: =UPPER(_xlfn.CONCAT(B3," ",C3)) -> AMIT ROY | E3: Male | F3: 48 | G3: D03 | H3: Executive | I3: 2021-12-18 | J3: 97903 | K3: Kolkata | L3: amit.roy2@example.com | M3: Active | N3: =VLOOKUP(G3,Departments!A2:C7,3,0) -> Carol | O3: =INDEX(Departments!C2:C7,MATCH(Employees!G3,Departments!A2:A7,0)) -> Carol
A4: E0003 | B4: Rohit | C4: Roy | D4: =UPPER(_xlfn.CONCAT(B4," ",C4)) -> ROHIT ROY | E4: Male | F4: 48 | G4: D04 | H4: Coordinator | I4: 2020-07-25 | J4: 73429 | K4: Pune | L4: rohit.roy3@example.com | M4: Inactive | N4: =VLOOKUP(G4,Departments!A3:C8,3,0) -> Dan | O4: =INDEX(Departments!C3:C8,MATCH(Employees!G4,Departments!A3:A8,0)) -> Dan
A5: E0004 | B5: David | C5: Dutta | D5: =UPPER(_xlfn.CONCAT(B5," ",C5)) -> DAVID DUTTA | E5: Female | F5: 50 | G5: D05 | H5: Manager | I5: 2021-08-05 | J5: 99336 | K5: Pune | L5: david.dutta4@example.com | M5: Active | N5: =VLOOKUP(G5,Departments!A4:C9,3,0) -> Eva | O5: =INDEX(Departments!C4:C9,MATCH(Employees!G5,Departments!A4:A9,0)) -> Eva | Q5: City | R5: JobTitle
A6: E0005 | B6: Jane | C6: Ghosh | D6: =UPPER(_xlfn.CONCAT(B6," ",C6)) -> JANE GHOSH | E6: Male | F6: 60 | G6: D01 | H6: Coordinator | I6: 2020-06-08 | J6: 105020 | K6: Pune | L6: jane.ghosh5@example.com | M6: Active | N6: =VLOOKUP(G6,Departments!A5:C10,3,0) -> #N/A | O6: =INDEX(Departments!C5:C10,MATCH(Employees!G6,Departments!A5:A10,0)) -> #N/A | Q6: Kolkata | R6: Analyst
A7: E0006 | B7: Rahul | C7: Dutta | D7: =UPPER(_xlfn.CONCAT(B7," ",C7)) -> RAHUL DUTTA | E7: Male | F7: 33 | G7: D02 | H7: Coordinator | I7: 2019-08-04 | J7: 93173 | K7: Pune | L7: rahul.dutta6@example.com | M7: Active | N7: =VLOOKUP(G7,Departments!A6:C11,3,0) -> #N/A | O7: =INDEX(Departments!C6:C11,MATCH(Employees!G7,Departments!A6:A11,0)) -> #N/A
A8: E0007 | B8: Sara | C8: Ghosh | D8: =UPPER(_xlfn.CONCAT(B8," ",C8)) -> SARA GHOSH | E8: Male | F8: 52 | G8: D05 | H8: Analyst | I8: 2021-01-23 | J8: 106626 | K8: Pune | L8: sara.ghosh7@example.com | M8: Active | N8: =VLOOKUP(G8,Departments!A7:C12,3,0) -> #N/A | O8: =INDEX(Departments!C7:C12,MATCH(Employees!G8,Departments!A7:A12,0)) -> #N/A | Q8: EmployeeID | R8: FirstName | S8: LastName | T8: Full Name | U8: Gender | V8: Age | W8: DepartmentID | X8: JobTitle | Y8: HireDate | Z8: Salary | AA8: City | AB8: Email | AC8: Status
A9: E0008 | B9: John | C9: Dutta | D9: =UPPER(_xlfn.CONCAT(B9," ",C9)) -> JOHN DUTTA | E9: Female | F9: 42 | G9: D02 | H9: Manager | I9: 2020-05-27 | J9: 114547 | K9: Delhi | L9: john.dutta8@example.com | M9: Inactive | N9: =VLOOKUP(G9,Departments!A8:C13,3,0) -> #N/A | O9: =INDEX(Departments!C8:C13,MATCH(Employees!G9,Departments!A8:A13,0)) -> #N/A | Q9: E0001 | R9: Amit | S9: Dutta | T9: AMIT DUTTA | U9: Female | V9: 30 | W9: D01 | X9: Analyst | Y9: 2019-02-21 | Z9: 105257 | AA9: Kolkata | AB9: amit.dutta1@example.com | AC9: Active
A10: E0009 | B10: John | C10: Singh | D10: =UPPER(_xlfn.CONCAT(B10," ",C10)) -> JOHN SINGH | E10: Female | F10: 40 | G10: D01 | H10: Coordinator | I10: 2022-04-30 | J10: 51139 | K10: Bengaluru | L10: john.singh9@example.com | M10: Inactive | N10: =VLOOKUP(G10,Departments!A9:C14,3,0) -> #N/A | O10: =INDEX(Departments!C9:C14,MATCH(Employees!G10,Departments!A9:A14,0)) -> #N/A | Q10: E0024 | R10: Jane | S10: Singh | T10: JANE SINGH | U10: Male | V10: 35 | W10: D02 | X10: Analyst | Y10: 2019-06-08 | Z10: 79578 | AA10: Kolkata | AB10: jane.singh24@example.com | AC10: Inactive
A11: E0010 | B11: Amit | C11: Roy | D11: =UPPER(_xlfn.CONCAT(B11," ",C11)) -> AMIT ROY | E11: Female | F11: 25 | G11: D05 | H11: Analyst | I11: 2018-12-23 | J11: 60673 | K11: Bengaluru | L11: amit.roy10@example.com | M11: Inactive | N11: =VLOOKUP(G11,Departments!A10:C15,3,0) -> #N/A | O11: =INDEX(Departments!C10:C15,MATCH(Employees!G11,Departments!A10:A15,0)) -> #N/A | Q11: E0107 | R11: Neha | S11: Singh | T11: NEHA SINGH | U11: Male | V11: 27 | W11: D04 | X11: Analyst | Y11: 2019-04-27 | Z11: 90958 | AA11: Kolkata | AB11: neha.singh107@example.com | AC11: Inactive
A12: E0011 | B12: Anita | C12: Roy | D12: =UPPER(_xlfn.CONCAT(B12," ",C12)) -> ANITA ROY | E12: Female | F12: 25 | G12: D05 | H12: Coordinator | I12: 2021-06-09 | J12: 65690 | K12: Kolkata | L12: anita.roy11@example.com | M12: Inactive | N12: =VLOOKUP(G12,Departments!A11:C16,3,0) -> #N/A | O12: =INDEX(Departments!C11:C16,MATCH(Employees!G12,Departments!A11:A16,0)) -> #N/A | Q12: E0118 | R12: Neha | S12: Khan | T12: NEHA KHAN | U12: Male | V12: 24 | W12: D04 | X12: Analyst | Y12: 2022-07-04 | Z12: 99200 | AA12: Kolkata | AB12: neha.khan118@example.com | AC12: Inactive
A13: E0012 | B13: Rohit | C13: Ghosh | D13: =UPPER(_xlfn.CONCAT(B13," ",C13)) -> ROHIT GHOSH | E13: Male | F13: 49 | G13: D03 | H13: Executive | I13: 2019-02-24 | J13: 63823 | K13: Bengaluru | L13: rohit.ghosh12@example.com | M13: Active | N13: =VLOOKUP(G13,Departments!A12:C17,3,0) -> #N/A | O13: =INDEX(Departments!C12:C17,MATCH(Employees!G13,Departments!A12:A17,0)) -> #N/A | Q13: E0167 | R13: David | S13: Khan | T13: DAVID KHAN | U13: Male | V13: 41 | W13: D05 | X13: Analyst | Y13: 2018-11-21 | Z13: 45748 | AA13: Kolkata | AB13: david.khan167@example.com | AC13: Inactive
A14: E0013 | B14: Rohit | C14: Khan | D14: =UPPER(_xlfn.CONCAT(B14," ",C14)) -> ROHIT KHAN | E14: Female | F14: 56 | G14: D05 | H14: Analyst | I14: 2022-03-31 | J14: 49557 | K14: Mumbai | L14: rohit.khan13@example.com | M14: Inactive | N14: =VLOOKUP(G14,Departments!A13:C18,3,0) -> #N/A | O14: =INDEX(Departments!C13:C18,MATCH(Employees!G14,Departments!A13:A18,0)) -> #N/A | Q14: E0183 | R14: Anita | S14: Sen | T14: ANITA SEN | U14: Male | V14: 60 | W14: D04 | X14: Analyst | Y14: 2024-06-20 | Z14: 111243 | AA14: Kolkata | AB14: anita.sen183@example.com | AC14: Active
A15: E0014 | B15: Rohit | C15: Sen | D15: =UPPER(_xlfn.CONCAT(B15," ",C15)) -> ROHIT SEN | E15: Male | F15: 44 | G15: D01 | H15: Coordinator | I15: 2022-09-23 | J15: 116901 | K15: Bengaluru | L15: rohit.sen14@example.com | M15: Active | N15: =VLOOKUP(G15,Departments!A14:C19,3,0) -> #N/A | O15: =INDEX(Departments!C14:C19,MATCH(Employees!G15,Departments!A14:A19,0)) -> #N/A | Q15: E0185 | R15: Neha | S15: Ghosh | T15: NEHA GHOSH | U15: Male | V15: 35 | W15: D05 | X15: Analyst | Y15: 2024-07-05 | Z15: 71247 | AA15: Kolkata | AB15: neha.ghosh185@example.com | AC15: Inactive
A16: E0015 | B16: David | C16: Sen | D16: =UPPER(_xlfn.CONCAT(B16," ",C16)) -> DAVID SEN | E16: Female | F16: 55 | G16: D02 | H16: Analyst | I16: 2018-07-03 | J16: 85190 | K16: Delhi | L16: david.sen15@example.com | M16: Inactive | N16: =VLOOKUP(G16,Departments!A15:C20,3,0) -> #N/A | O16: =INDEX(Departments!C15:C20,MATCH(Employees!G16,Departments!A15:A20,0)) -> #N/A | Q16: E0264 | R16: Priya | S16: Das | T16: PRIYA DAS | U16: Female | V16: 44 | W16: D03 | X16: Analyst | Y16: 2018-03-24 | Z16: 97265 | AA16: Kolkata | AB16: priya.das264@example.com | AC16: Active
A17: E0016 | B17: Sara | C17: Paul | D17: =UPPER(_xlfn.CONCAT(B17," ",C17)) -> SARA PAUL | E17: Female | F17: 30 | G17: D04 | H17: Coordinator | I17: 2024-04-11 | J17: 95723 | K17: Bengaluru | L17: sara.paul16@example.com | M17: Inactive | N17: =VLOOKUP(G17,Departments!A16:C21,3,0) -> #N/A | O17: =INDEX(Departments!C16:C21,MATCH(Employees!G17,Departments!A16:A21,0)) -> #N/A | Q17: E0311 | R17: Sara | S17: Roy | T17: SARA ROY | U17: Female | V17: 27 | W17: D02 | X17: Analyst | Y17: 2018-08-10 | Z17: 86048 | AA17: Kolkata | AB17: sara.roy311@example.com | AC17: Active
A18: E0017 | B18: Priya | C18: Smith | D18: =UPPER(_xlfn.CONCAT(B18," ",C18)) -> PRIYA SMITH | E18: Female | F18: 51 | G18: D04 | H18: Executive | I18: 2019-04-23 | J18: 35234 | K18: Delhi | L18: priya.smith17@example.com | M18: Inactive | N18: =VLOOKUP(G18,Departments!A17:C22,3,0) -> #N/A | O18: =INDEX(Departments!C17:C22,MATCH(Employees!G18,Departments!A17:A22,0)) -> #N/A | Q18: E0319 | R18: David | S18: Smith | T18: DAVID SMITH | U18: Female | V18: 53 | W18: D04 | X18: Analyst | Y18: 2020-07-26 | Z18: 50653 | AA18: Kolkata | AB18: david.smith319@example.com | AC18: Inactive
A19: E0018 | B19: John | C19: Roy | D19: =UPPER(_xlfn.CONCAT(B19," ",C19)) -> JOHN ROY | E19: Male | F19: 38 | G19: D01 | H19: Executive | I19: 2018-07-10 | J19: 102733 | K19: Kolkata | L19: john.roy18@example.com | M19: Inactive | N19: =VLOOKUP(G19,Departments!A18:C23,3,0) -> #N/A | O19: =INDEX(Departments!C18:C23,MATCH(Employees!G19,Departments!A18:A23,0)) -> #N/A | Q19: E0362 | R19: Anita | S19: Dutta | T19: ANITA DUTTA | U19: Male | V19: 60 | W19: D01 | X19: Analyst | Y19: 2024-06-01 | Z19: 117041 | AA19: Kolkata | AB19: anita.dutta362@example.com | AC19: Inactive
A20: E0019 | B20: Rohit | C20: Khan | D20: =UPPER(_xlfn.CONCAT(B20," ",C20)) -> ROHIT KHAN | E20: Female | F20: 46 | G20: D01 | H20: Manager | I20: 2022-08-16 | J20: 76829 | K20: Bengaluru | L20: rohit.khan19@example.com | M20: Active | N20: =VLOOKUP(G20,Departments!A19:C24,3,0) -> #N/A | O20: =INDEX(Departments!C19:C24,MATCH(Employees!G20,Departments!A19:A24,0)) -> #N/A | Q20: E0367 | R20: Sara | S20: Khan | T20: SARA KHAN | U20: Male | V20: 42 | W20: D03 | X20: Analyst | Y20: 2019-05-14 | Z20: 106833 | AA20: Kolkata | AB20: sara.khan367@example.com | AC20: Inactive
... A25: E0024 | B25: Jane | C25: Singh | D25: =UPPER(_xlfn.CONCAT(B25," ",C25)) -> JANE SINGH | E25: Male | F25: 35 | G25: D02 | H25: Analyst | I25: 2019-06-08 | J25: 79578 | K25: Kolkata | L25: jane.singh24@example.com | M25: Inactive | N25: =VLOOKUP(G25,Departments!A24:C29,3,0) -> #N/A | O25: =INDEX(Departments!C24:C29,MATCH(Employees!G25,Departments!A24:A29,0)) -> #N/A | Q25: E0424 | R25: Amit | S25: Singh | T25: AMIT SINGH | U25: Female | V25: 24 | W25: D04 | X25: Analyst | Y25: 2019-06-29 | Z25: 57088 | AA25: Kolkata | AB25: amit.singh424@example.com | AC25: Active
A26: E0025 | B26: Anita | C26: Sen | D26: =UPPER(_xlfn.CONCAT(B26," ",C26)) -> ANITA SEN | E26: Male | F26: 47 | G26: D03 | H26: Specialist | I26: 2021-12-07 | J26: 111899 | K26: Bengaluru | L26: anita.sen25@example.com | M26: Inactive | N26: =VLOOKUP(G26,Departments!A25:C30,3,0) -> #N/A | O26: =INDEX(Departments!C25:C30,MATCH(Employees!G26,Departments!A25:A30,0)) -> #N/A
A27: E0026 | B27: John | C27: Dutta | D27: =UPPER(_xlfn.CONCAT(B27," ",C27)) -> JOHN DUTTA | E27: Male | F27: 47 | G27: D04 | H27: Executive | I27: 2023-06-24 | J27: 95862 | K27: Kolkata | L27: john.dutta26@example.com | M27: Active | N27: =VLOOKUP(G27,Departments!A26:C31,3,0) -> #N/A | O27: =INDEX(Departments!C26:C31,MATCH(Employees!G27,Departments!A26:A31,0)) -> #N/A
A28: E0027 | B28: Amit | C28: Sen | D28: =UPPER(_xlfn.CONCAT(B28," ",C28)) -> AMIT SEN | E28: Female | F28: 49 | G28: D03 | H28: Analyst | I28: 2020-10-09 | J28: 110397 | K28: Mumbai | L28: amit.sen27@example.com | M28: Inactive | N28: =VLOOKUP(G28,Departments!A27:C32,3,0) -> #N/A | O28: =INDEX(Departments!C27:C32,MATCH(Employees!G28,Departments!A27:A32,0)) -> #N/A | Q28: 1. create a full name column of the employee beside/after last name column using text formula.
A29: E0028 | B29: Jane | C29: Das | D29: =UPPER(_xlfn.CONCAT(B29," ",C29)) -> JANE DAS | E29: Female | F29: 27 | G29: D02 | H29: Executive | I29: 2021-06-08 | J29: 111149 | K29: Mumbai | L29: jane.das28@example.com | M29: Active | N29: =VLOOKUP(G29,Departments!A28:C33,3,0) -> #N/A | O29: =INDEX(Departments!C28:C33,MATCH(Employees!G29,Departments!A28:A33,0)) -> #N/A | Q29: 2. using text func find the full name of the emplloyee in uppercase letter.
A30: E0029 | B30: Sara | C30: Khan | D30: =UPPER(_xlfn.CONCAT(B30," ",C30)) -> SARA KHAN | E30: Male | F30: 36 | G30: D04 | H30: Analyst | I30: 2022-02-08 | J30: 67035 | K30: Mumbai | L30: sara.khan29@example.com | M30: Inactive | N30: =VLOOKUP(G30,Departments!A29:C34,3,0) -> #N/A | O30: =INDEX(Departments!C29:C34,MATCH(Employees!G30,Departments!A29:A34,0)) -> #N/A | Q30: 3. count the number of femal employees.
A31: E0030 | B31: David | C31: Dutta | D31: =UPPER(_xlfn.CONCAT(B31," ",C31)) -> DAVID DUTTA | E31: Male | F31: 41 | G31: D03 | H31: Analyst | I31: 2021-05-20 | J31: 103851 | K31: Pune | L31: david.dutta30@example.com | M31: Inactive | N31: =VLOOKUP(G31,Departments!A30:C35,3,0) -> #N/A | O31: =INDEX(Departments!C30:C35,MATCH(Employees!G31,Departments!A30:A35,0)) -> #N/A | Q31: 4. filter the employees of the kolkata city & job title list should analyst and place the filter data to another place.
A32: E0031 | B32: Amit | C32: Ghosh | D32: =UPPER(_xlfn.CONCAT(B32," ",C32)) -> AMIT GHOSH | E32: Female | F32: 26 | G32: D05 | H32: Specialist | I32: 2019-08-08 | J32: 63676 | K32: Kolkata | L32: amit.ghosh31@example.com | M32: Inactive | N32: =VLOOKUP(G32,Departments!A31:C36,3,0) -> #N/A | O32: =INDEX(Departments!C31:C36,MATCH(Employees!G32,Departments!A31:A36,0)) -> #N/A | Q32: 5. highlight the active employees records.
A33: E0032 | B33: Neha | C33: Smith | D33: =UPPER(_xlfn.CONCAT(B33," ",C33)) -> NEHA SMITH | E33: Female | F33: 31 | G33: D01 | H33: Manager | I33: 2019-11-15 | J33: 115269 | K33: Mumbai | L33: neha.smith32@example.com | M33: Inactive | N33: =VLOOKUP(G33,Departments!A32:C37,3,0) -> #N/A | O33: =INDEX(Departments!C32:C37,MATCH(Employees!G33,Departments!A32:A37,0)) -> #N/A | Q33: 6. creat a column dept : name in employees workheet and fetch the records from the dept worksheets ( using vlookup formula )
A34: E0033 | B34: Neha | C34: Singh | D34: =UPPER(_xlfn.CONCAT(B34," ",C34)) -> NEHA SINGH | E34: Male | F34: 47 | G34: D04 | H34: Analyst | I34: 2019-06-18 | J34: 77203 | K34: Pune | L34: neha.singh33@example.com | M34: Active | N34: =VLOOKUP(G34,Departments!A33:C38,3,0) -> #N/A | O34: =INDEX(Departments!C33:C38,MATCH(Employees!G34,Departments!A33:A38,0)) -> #N/A | Q34: 7. create a column : manager in empoyee worksheet using and fetch the records of the dept worksheet using index and match.
A35: E0034 | B35: John | C35: Sen | D35: =UPPER(_xlfn.CONCAT(B35," ",C35)) -> JOHN SEN | E35: Male | F35: 57 | G35: D01 | H35: Specialist | I35: 2024-03-15 | J35: 113291 | K35: Mumbai | L35: john.sen34@example.com | M35: Inactive | N35: =VLOOKUP(G35,Departments!A34:C39,3,0) -> #N/A | O35: =INDEX(Departments!C34:C39,MATCH(Employees!G35,Departments!A34:A39,0)) -> #N/A
A36: E0035 | B36: David | C36: Khan | D36: =UPPER(_xlfn.CONCAT(B36," ",C36)) -> DAVID KHAN | E36: Female | F36: 45 | G36: D01 | H36: Analyst | I36: 2021-11-25 | J36: 93729 | K36: Mumbai | L36: david.khan35@example.com | M36: Inactive | N36: =VLOOKUP(G36,Departments!A35:C40,3,0) -> #N/A | O36: =INDEX(Departments!C35:C40,MATCH(Employees!G36,Departments!A35:A40,0)) -> #N/A
A37: E0036 | B37: Rohit | C37: Ghosh | D37: =UPPER(_xlfn.CONCAT(B37," ",C37)) -> ROHIT GHOSH | E37: Male | F37: 40 | G37: D05 | H37: Specialist | I37: 2018-06-15 | J37: 35947 | K37: Bengaluru | L37: rohit.ghosh36@example.com | M37: Inactive | N37: =VLOOKUP(G37,Departments!A36:C41,3,0) -> #N/A | O37: =INDEX(Departments!C36:C41,MATCH(Employees!G37,Departments!A36:A41,0)) -> #N/A
A38: E0037 | B38: Amit | C38: Ghosh | D38: =UPPER(_xlfn.CONCAT(B38," ",C38)) -> AMIT GHOSH | E38: Female | F38: 49 | G38: D05 | H38: Executive | I38: 2021-05-24 | J38: 72311 | K38: Mumbai | L38: amit.ghosh37@example.com | M38: Inactive | N38: =VLOOKUP(G38,Departments!A37:C42,3,0) -> #N/A | O38: =INDEX(Departments!C37:C42,MATCH(Employees!G38,Departments!A37:A42,0)) -> #N/A
A39: E0038 | B39: Neha | C39: Paul | D39: =UPPER(_xlfn.CONCAT(B39," ",C39)) -> NEHA PAUL | E39: Male | F39: 53 | G39: D02 | H39: Manager | I39: 2020-11-13 | J39: 38763 | K39: Delhi | L39: neha.paul38@example.com | M39: Active | N39: =VLOOKUP(G39,Departments!A38:C43,3,0) -> #N/A | O39: =INDEX(Departments!C38:C43,MATCH(Employees!G39,Departments!A38:A43,0)) -> #N/A
A40: E0039 | B40: David | C40: Brown | D40: =UPPER(_xlfn.CONCAT(B40," ",C40)) -> DAVID BROWN | E40: Female | F40: 54 | G40: D04 | H40: Coordinator | I40: 2018-06-20 | J40: 101175 | K40: Delhi | L40: david.brown39@example.com | M40: Active | N40: =VLOOKUP(G40,Departments!A39:C44,3,0) -> #N/A | O40: =INDEX(Departments!C39:C44,MATCH(Employees!G40,Departments!A39:A44,0)) -> #N/A
A41: E0040 | B41: Neha | C41: Paul | D41: =UPPER(_xlfn.CONCAT(B41," ",C41)) -> NEHA PAUL | E41: Female | F41: 41 | G41: D03 | H41: Specialist | I41: 2018-11-27 | J41: 36386 | K41: Bengaluru | L41: neha.paul40@example.com | M41: Active | N41: =VLOOKUP(G41,Departments!A40:C45,3,0) -> #N/A | O41: =INDEX(Departments!C40:C45,MATCH(Employees!G41,Departments!A40:A45,0)) -> #N/A
A42: E0041 | B42: Anita | C42: Ghosh | D42: =UPPER(_xlfn.CONCAT(B42," ",C42)) -> ANITA GHOSH | E42: Female | F42: 56 | G42: D05 | H42: Manager | I42: 2021-11-26 | J42: 76395 | K42: Kolkata | L42: anita.ghosh41@example.com | M42: Inactive | N42: =VLOOKUP(G42,Departments!A41:C46,3,0) -> #N/A | O42: =INDEX(Departments!C41:C46,MATCH(Employees!G42,Departments!A41:A46,0)) -> #N/A
A43: E0042 | B43: Jane | C43: Smith | D43: =UPPER(_xlfn.CONCAT(B43," ",C43)) -> JANE SMITH | E43: Male | F43: 49 | G43: D04 | H43: Specialist | I43: 2019-01-24 | J43: 43701 | K43: Delhi | L43: jane.smith42@example.com | M43: Active | N43: =VLOOKUP(G43,Departments!A42:C47,3,0) -> #N/A | O43: =INDEX(Departments!C42:C47,MATCH(Employees!G43,Departments!A42:A47,0)) -> #N/A
A44: E0043 | B44: Priya | C44: Das | D44: =UPPER(_xlfn.CONCAT(B44," ",C44)) -> PRIYA DAS | E44: Male | F44: 32 | G44: D03 | H44: Analyst | I44: 2018-01-16 | J44: 85198 | K44: Delhi | L44: priya.das43@example.com | M44: Active | N44: =VLOOKUP(G44,Departments!A43:C48,3,0) -> #N/A | O44: =INDEX(Departments!C43:C48,MATCH(Employees!G44,Departments!A43:A48,0)) -> #N/A
...

Sheet Departments
A1: DepartmentID | B1: DepartmentName | C1: Manager
A2: D01 | B2: HR | C2: Alice
A3: D02 | B3: Finance | C3: Bob
A4: D03 | B4: IT | C4: Carol
A5: D04 | B5: Sales | C5: Dan
A6: D05 | B6: Marketing | C6: Eva

Sheet Performance
A1: EmployeeID | B1: ReviewYear | C1: Rating | D1: TrainingHours | E1: ProjectsCompleted
A2: E0001 | B2: 2026 | C2: 1 | D2: 4 | E2: 2
A3: E0002 | B3: 2026 | C3: 4 | D3: 5 | E3: 7
A4: E0003 | B4: 2026 | C4: 2 | D4: 29 | E4: 5
A5: E0004 | B5: 2026 | C5: 4 | D5: 18 | E5: 6
A6: E0005 | B6: 2026 | C6: 2 | D6: 48 | E6: 2
A7: E0006 | B7: 2026 | C7: 3 | D7: 14 | E7: 5
A8: E0007 | B8: 2026 | C8: 2 | D8: 19 | E8: 3
A9: E0008 | B9: 2026 | C9: 1 | D9: 4 | E9: 2
A10: E0009 | B10: 2026 | C10: 4 | D10: 59 | E10: 0
A11: E0010 | B11: 2026 | C11: 5 | D11: 27 | E11: 2
A12: E0011 | B12: 2026 | C12: 3 | D12: 42 | E12: 3
A13: E0012 | B13: 2026 | C13: 2 | D13: 59 | E13: 3
... A501: E0500 | B501: 2026 | C501: 3 | D501: 47 | E501: 8
